<?xml version="1.0"?>
<robot name="kachaka_robot" xmlns:xacro="http://ros.org/wiki/xacro">
  <xacro:macro name="kachaka_robot" params="parent *origin">
    <!-- base_footprint -->
    <joint name="base_footprint_joint"
           type="fixed">
      <parent link="${parent}" />
      <child link="base_footprint" />
      <xacro:insert_block name="origin" />
    </joint>
    <link name="base_link">
      <inertial>
        <mass value="10.0" />
        <origin xyz="0.0435 0.0 0.0475"
                rpy="0 0 0" />
        <inertia ixx="${1/12*10*(0.095**2+0.240**2)}" ixy="0" ixz="0"
                iyy="${1/12*10*(0.095**2+0.387**2)}" iyz="0"
                izz="${1/12*10*(0.387**2+0.240**2)}" />
      </inertial>
      <visual>
        <origin rpy="0 0 0" xyz="-0.150 -0.120 0.0"/>
        <geometry>
          <mesh filename="package://kachaka_description/meshes/kachaka/body.stl"/>
        </geometry>
        <material name="body" />
      </visual>
      <collision>
        <origin xyz="0.0435 0.0 0.0475"
                rpy="0 0 0" />
        <geometry>
          <box size="0.387 0.240 0.095" />
        </geometry>
        <material name="body" />
      </collision>
    </link>

    <!-- Wheel(right) -->
    <joint name="base_r_drive_wheel_joint"
          type="continuous">
      <parent link="base_link" />
      <child link="base_r_drive_wheel_link" />
      <origin rpy="0 0 0"
              xyz="0.0 -0.100 0.045" />
      <axis xyz="0 1 0" />
    </joint>
    <link name="base_r_drive_wheel_link">
      <inertial>
        <mass value="0.2" /> <!-- TODO - Update mass value -->
        <origin xyz="0 0 0"
                rpy="${PI / 2.0} 0 0" />
        <!-- Bug - inertial rotation is not reflected in Rviz2 -->
        <!-- https://github.com/ros2/rviz/pull/1316 -->
        <inertia ixx="${1/12*0.2*(3*0.045**2+0.025**2)}" ixy="0" ixz="0"
                iyy="${1/12*0.2*(3*0.045**2+0.025**2)}" iyz="0"
                izz="${1/2*0.2*(0.045**2)}" />
      </inertial>
      <visual>
        <origin rpy="0 0 0" xyz="0 0 0"/>
        <geometry>
          <mesh filename="package://kachaka_description/meshes/kachaka/right_tire.stl" scale="1.0 1.0 1.0"/>
        </geometry>
        <material name="tire" />
      </visual>
      <collision>
        <origin xyz="0 0 0"
                rpy="1.57079637 0 0" />
        <geometry>
          <cylinder length="0.025"
                    radius="0.0475" />
        </geometry>
        <material name="tire" />
        <surface>
          <friction>
            <ode>
              <mu>1</mu>
              <mu2>1</mu2>
              <slip1>0.035</slip1>
              <slip2>0</slip2>
              <fdir1>0 0 1</fdir1>
            </ode>
          </friction>
          <contact>
            <ode>
              <soft_cfm>0</soft_cfm>
              <soft_erp>0.2</soft_erp>
              <kp>1e+5</kp>
              <kd>1</kd>
              <max_vel>0.01</max_vel>
              <min_depth>0.001</min_depth>
            </ode>
          </contact>
        </surface>
      </collision>
    </link>

    <!-- Wheel(left) -->
    <joint name="base_l_drive_wheel_joint"
          type="continuous">
      <parent link="base_link" />
      <child link="base_l_drive_wheel_link" />
      <origin rpy="0 0 0"
              xyz="0.0 0.100 0.045" />
      <axis xyz="0 1 0" />
    </joint>
    <link name="base_l_drive_wheel_link">
      <inertial>
        <mass value="0.2" />
        <origin xyz="0 0 0"
                rpy="1.57079637 0 0" />
        <!-- Bug - inertial rotation is not reflected in Rviz2 -->
        <!-- https://github.com/ros2/rviz/pull/1316 -->
        <inertia ixx="${1/12*0.2*(3*0.045**2+0.025**2)}" ixy="0" ixz="0"
                iyy="${1/12*0.2*(3*0.045**2+0.025**2)}" iyz="0"
                izz="${1/2*0.2*(0.045**2)}" />
      </inertial>
      <visual>
        <origin xyz="0 0 0"
                rpy="0 0 0" />
        <geometry>
          <mesh filename="package://kachaka_description/meshes/kachaka/left_tire.stl" scale="1.0 1.0 1.0"/>
        </geometry>
        <material name="tire" />
      </visual>
      <collision>
        <origin xyz="0 0 0"
                rpy="1.57079637 0 0" />
        <geometry>
          <cylinder length="0.025"
                    radius="0.0475" />
        </geometry>
        <material name="tire" />
        <surface>
          <friction>
            <ode>
              <mu>1</mu>
              <mu2>1</mu2>
              <slip1>0.035</slip1>
              <slip2>0</slip2>
              <fdir1>0 0 1</fdir1>
            </ode>
          </friction>
          <contact>
            <ode>
              <soft_cfm>0</soft_cfm>
              <soft_erp>0.2</soft_erp>
              <kp>1e+5</kp>
              <kd>1</kd>
              <max_vel>0.01</max_vel>
              <min_depth>0.001</min_depth>
            </ode>
          </contact>
        </surface>
      </collision>
    </link>

    <gazebo>
        <plugin
          filename="gz-sim-diff-drive-system"
          name="gz::sim::systems::DiffDrive">
          <left_joint>base_l_drive_wheel_joint</left_joint>
          <right_joint>base_r_drive_wheel_joint</right_joint>
          <wheel_separation>0.2</wheel_separation>
          <wheel_radius>0.0475</wheel_radius>
          <max_linear_acceleration>2</max_linear_acceleration>
          <min_linear_acceleration>-2</min_linear_acceleration>
          <max_angular_acceleration>3</max_angular_acceleration>
          <min_angular_acceleration>-3</min_angular_acceleration>
          <max_linear_velocity>0.8</max_linear_velocity>
          <min_linear_velocity>-0.8</min_linear_velocity>
          <max_angular_velocity>2.0</max_angular_velocity>
          <min_angular_velocity>-2.0</min_angular_velocity>
          <topic>/kachaka/manual_control/cmd_vel</topic>
          <odom_topic>/kachaka/wheel_odometry/wheel_odometry</odom_topic>
          <tf_topic>tf</tf_topic>
          <frame_id>odom</frame_id>
          <child_frame_id>base_link</child_frame_id>
          <odom_publish_frequency>10</odom_publish_frequency>
        </plugin>

        <plugin
          filename="gz-sim-joint-state-publisher-system"
          name="gz::sim::systems::JointStatePublisher">
          <topic>/kachaka/joint_states</topic>
          <update_rate>30</update_rate>
        </plugin>
    </gazebo>

    <!-- 2D LiDAR -->
    <joint name="lidar_joint"
          type="fixed">
      <parent link="base_link" />
      <child link="laser_frame" />
      <!-- Changed the height of 2D LiDAR to avoid the problem of Gazebo -->
      <origin rpy="0 0 ${PI / 2.0}"
              xyz="0.156 0 0.1549" />
    </joint>
    <link name="laser_frame" />
    <gazebo reference="laser_frame">
      <sensor type="gpu_lidar" name="lasor_sensor">
        <pose>0 0 0 0 0 0</pose>
        <topic>/kachaka/lidar/scan</topic>
        <visualize>false</visualize>
        <update_rate>10</update_rate>
        <gz_frame_id>laser_frame</gz_frame_id>
        <lidar>
          <scan>
            <horizontal>
              <samples>400</samples>
              <resolution>1</resolution>
              <min_angle>-3.66519</min_angle>
              <max_angle>0.523599</max_angle>
            </horizontal>
          </scan>
          <range>
            <min>0.1</min>
            <max>10.0</max>
            <resolution>0.001</resolution>
          </range>
          <noise>
            <type>gaussian</type>
            <mean>0.0</mean>
            <stddev>0.03</stddev>
          </noise>
        </lidar>
      </sensor>
    </gazebo>

    <!-- Camera(front) -->
    <joint name="camera_front_joint"
          type="fixed">
      <parent link="base_link" />
      <child link="camera_front_link" />
      <origin rpy="0 0 0"
              xyz="${0.2196 - 0.01} 0 0.070" />
    </joint>
    <link name="camera_front_link" />
    <link name="camera_front_optical_link"/>
    <joint name="camera_front_optical_joint" type="fixed">
      <origin xyz="0 0 0" rpy="-${PI / 2.0} 0.0 -${PI / 2.0}"/>
      <parent link="camera_front_link"/>
      <child link="camera_front_optical_link"/>
    </joint>
    <gazebo reference="camera_front_link">
      <sensor name="front_rgb_camera_sensor" type="camera">
        <pose>0 0 0 0 0 0</pose>
        <always_on>1</always_on>
        <update_rate>10</update_rate>
        <topic>/kachaka/front_camera/image_raw</topic>
        <optical_frame_id>camera_front_optical_link</optical_frame_id>
        <camera>
          <image>
            <width>1280</width>
            <height>720</height>
          </image>
        </camera>
      </sensor>
    </gazebo>

    <!-- Camera(back) -->
    <joint name="camera_back_joint"
          type="fixed">
      <parent link="base_link" />
      <child link="camera_back_link" />
      <origin rpy="0 0 ${PI}"
              xyz="${-0.150 + 0.01} 0 0.070" />
    </joint>
    <link name="camera_back_link" />
    <link name="camera_back_optical_link"/>
    <joint name="camera_back_optical_joint" type="fixed">
      <origin xyz="0 0 0" rpy="-${PI / 2.0} 0.0 -${PI / 2.0}"/>
      <parent link="camera_back_link"/>
      <child link="camera_back_optical_link"/>
    </joint>
    <gazebo reference="camera_back_link">
      <sensor name="back_rgb_camera_sensor" type="camera">
        <pose>0 0 0 0 0 0</pose>
        <always_on>1</always_on>
        <update_rate>10</update_rate>
        <topic>/kachaka/back_camera/image_raw</topic>
        <optical_frame_id>camera_back_optical_link</optical_frame_id>
        <camera>
          <image>
            <width>1280</width>
            <height>720</height>
          </image>
        </camera>
      </sensor>
    </gazebo>

    <!-- ToF camera -->
    <joint name="tof_joint"
          type="fixed">
      <parent link="base_link" />
      <child link="tof_link" />
      <!-- Changed camera position to avoid a problem of depth camera
      <origin rpy="0 -${PI / 4.0} 0"
              xyz="0.221 0.0 0.0418" />
      -->
      <origin rpy="0 -${PI / 4.0} 0"
              xyz="0.225 0.0 0.0418" />
    </joint>
    <link name="tof_link" />
    <link name="tof_optical_link"/>
    <joint name="tof_optical_joint" type="fixed">
      <origin xyz="0 0 0" rpy="-${PI / 2.0} 0.0 -${PI / 2.0}"/>
      <parent link="tof_link"/>
      <child link="tof_optical_link"/>
    </joint>
    <gazebo reference="tof_link">
      <sensor name="tof_sensor" type="depth">
        <pose>0 0 0 0 0 0</pose>
        <always_on>1</always_on>
        <update_rate>10</update_rate>
        <topic>/kachaka/tof_camera/image_raw</topic>
        <optical_frame_id>tof_optical_link</optical_frame_id>
        <camera>
          <image>
            <width>160</width>
            <height>120</height>
          </image>
          <depth_camera>
            <clip>
              <near>0.01</near>
              <far>5.0</far>
            </clip>
           </depth_camera>
        </camera>
      </sensor>
    </gazebo>

    <!-- Docking -->
    <joint name="docking_joint"
          type="prismatic">
      <parent link="base_link" />
      <child link="docking_link" />
      <axis xyz="0 0 1.0" />
      <origin rpy="0 0 0"
              xyz="0 0 0" />
      <limit lower="0.0"
            upper="0.012"
            effort="1.0"
            velocity="1.0" />
    </joint>
    <link name="docking_link">
      <inertial>
        <mass value="0.2" /> <!-- TODO - Update mass value -->
        <origin xyz="0 0 0.1075"
                rpy="0 0 0" />
        <inertia ixx="${1/12*0.2*(3*0.025**2+0.015**2)}" ixy="0" ixz="0"
                 iyy="${1/12*0.2*(3*0.025**2+0.015**2)}" iyz="0"
                 izz="${1/2*0.2*(0.025**2)}" />
      </inertial>
      <visual>
        <geometry>
          <mesh filename="package://kachaka_description/meshes/kachaka/solenoid.stl"
                scale="1.0 1.0 1.0" />
        </geometry>
        <material name="body" />
      </visual>
      <collision>
        <origin xyz="0 0 0.1075"
                rpy="0 0 0" />
        <geometry>
          <cylinder length="0.015"
                    radius="0.025" />
        </geometry>
        <material name="body" />
      </collision>
    </link>

    <!-- IMU -->
    <joint name="imu_joint"
          type="fixed">
      <parent link="base_link" />
      <child link="imu_link" />
      <origin rpy="0 0 0"
              xyz="0.0756 -0.0655 0.05146" />
    </joint>
    <link name="imu_link" />
    <gazebo reference="imu_link">
      <gravity>true</gravity>
      <sensor name="imu_sensor" type="imu">
        <pose>0 0 0 0 0 0</pose>
        <always_on>1</always_on>
        <update_rate>10</update_rate>
        <visualize>true</visualize>
        <topic>/kachaka/imu/imu</topic>
      </sensor>
    </gazebo>

    <!-- Caster1 -->
    <joint name="caster1_joint" type="fixed">
      <parent link="base_link"/>
      <child link="caster1_link"/>
      <origin xyz="0.19 0.075 0.01" rpy="0 0 0"/>
    </joint>
    <link name="caster1_link">
      <visual>
        <geometry>
          <sphere radius="0.01"/>
        </geometry>
        <material name="tire" />
      </visual>
      <collision>
        <geometry>
          <sphere radius="0.01"/>
        </geometry>
      </collision>
      <inertial>
        <mass value="0.01" />
        <inertia ixx="${(2/5) * 0.01 * 0.01 * 0.01}" ixy="0.0" ixz="0.0"
                 iyy="${(2/5) * 0.01 * 0.01 * 0.01}" iyz="0.0"
                 izz="${(2/5) * 0.01 * 0.01 * 0.01}" />
      </inertial>
    </link>

    <gazebo reference="caster1_joint">
      <preserveFixedJoint>true</preserveFixedJoint>
    </gazebo>

    <gazebo reference="caster1_link">
      <mu1>0.0</mu1>
      <mu2>0.0</mu2>
      <kp>1000000.0</kp>
      <kd>1.0</kd>
    </gazebo>

    <!-- Caster2 -->
    <joint name="caster2_joint" type="fixed">
      <parent link="base_link"/>
      <child link="caster2_link"/>
      <origin xyz="0.19 -0.075 0.01" rpy="0 0 0"/>
    </joint>
    <link name="caster2_link">
      <visual>
        <geometry>
          <sphere radius="0.01"/>
        </geometry>
        <material name="tire" />
      </visual>
      <collision>
        <geometry>
          <sphere radius="0.01"/>
        </geometry>
      </collision>
      <inertial>
        <mass value="0.01" />
        <inertia ixx="${(2/5) * 0.01 * 0.01 * 0.01}" ixy="0.0" ixz="0.0"
                 iyy="${(2/5) * 0.01 * 0.01 * 0.01}" iyz="0.0"
                 izz="${(2/5) * 0.01 * 0.01 * 0.01}" />
      </inertial>
    </link>

    <gazebo reference="caster2_joint">
      <preserveFixedJoint>true</preserveFixedJoint>
    </gazebo>

    <gazebo reference="caster2_link">
      <mu1>0.0</mu1>
      <mu2>0.0</mu2>
      <kp>1000000.0</kp>
      <kd>1.0</kd>
    </gazebo>

  </xacro:macro>
</robot>
